<mujoco>
   <visual>
      <headlight ambient="1 1 1" />
   </visual>

   <option gravity="0 0 -2" />

   <worldbody>
      <light diffuse=".5 .5 .5" pos="0 0 3" dir="0 0 -1"/>

      <geom type="plane" size="3 3 0.1" rgba=".6 .6 .6 1"/>

      <body pos="0 0 5" euler="0 0 0">
         <joint type="slide" name="x-slide" axis="1 0 0"/>
         <joint type="slide" name="y-slide" axis="0 1 0"/>
         <joint type="slide" name="z-slide" axis="0 0 1"/> 
         <geom type="sphere" size=".05" rgba="255 0 0 1" mass="10"/>

         <body pos="-0.5 0 -2.5" euler="0 90 0">
            <joint type="slide" name="arm1"/>
            <geom type="box" size=".2 .2 .05" rgba="255 128 0 1" mass="100"/>
         </body>
         <body pos="0.5 0 -2.5" euler="0 -90 0">
            <joint type="slide" name="arm2"/>
            <geom type="box" size=".2 .2 .05" rgba="255 0 255 1" mass="100"/>
         </body>
      </body>

      <body pos="0 0 0.1" euler="0 0 0">
         <joint type = "free"/>
         <geom type="box" size=".1 .1 .1" rgba="0.7 0 0 1"/>
      </body>

      <body pos="0.7 0.5 0.1" euler="0 0 0">
         <joint type = "free"/>
         <geom type="sphere" size=".1" rgba="0 0.2 0.5 1"/>
      </body>

      <body name="yellow_box" pos="-0.7 0.2 .3" euler="0 0 90">
         <joint type = "free"/>
         <geom type="box" size=".1 .2 .3" rgba="0.6 0.6 0 1"/>
      </body>

      <body name="big_ball" pos="-0.5 -1.2 .3" euler="0 0 0">
         <joint type = "free"/>
         <geom type="sphere" size=".3" rgba="0 .4 .4 1"/>
      </body>

      <body name="blue_box" pos="0 .7 .3" euler="0 0 30">
         <joint type = "free"/>
         <geom type="box" size=".1 .2 .3" rgba="0 .5 .5 1"/>
      </body>

      <body pos="0 -.6 .06" euler="0 0 0">
         <joint type = "free"/>
         <geom type="sphere" size=".06" rgba=".3 .15 .5 1"/>
      </body>

      <body pos=".7 -.6 .2" euler="0 0 0">
         <joint type = "free"/>
         <geom type="box" size=".1 .1 .2" rgba=".3 .5 .2 1"/>
      </body>

   </worldbody>
   <actuator>

      <position name="x-pos" joint="x-slide" kp="1000" ctrllimited="true" ctrlrange="-2 2"/>
      <position name="y-pos" joint="y-slide" kp="1000" ctrllimited="true" ctrlrange="-2 2"/>     
      <position name="z-pos" joint="z-slide" kp="1000" ctrllimited="true" ctrlrange="-2 2"/>
      <position name="armp1" joint="arm1" kp="2000" ctrllimited="true" ctrlrange="-0.5 0.5"/>
      <position name="armp2" joint="arm2" kp="2000" ctrllimited="true" ctrlrange="-0.5 0.5"/>
      
      <velocity name="x-vel" joint="x-slide" kv="1000"/>
      <velocity name="y-vel" joint="y-slide" kv="1000"/>
      <velocity name="z-vel" joint="z-slide" kv="1000"/>
      <velocity name="armv1" joint="arm1" kv="2000"/>
      <velocity name="armv2" joint="arm2" kv="2000"/>

   </actuator>
</mujoco>